Workbook

Sheet Sheet1
A1: Lead ID | B1: Store Name | C1: Lead Type | D1: Lead Date | E1: Pre-Booking Date | F1: Booking Date | G1: Delivery Date | H1: Delivery Status | I1: Cancellation Status | J1: Cancellation Reason | K1: Service Follow-up Date | L1: TAT Pre-Booking (Days) | M1: TAT Booking (Days) | N1: TAT Delivery (Days) | O1: Customer Rating | P1: Feedback
A2: L1000 | B2: Bangalore MBC | C2: Warm | D2: 45951 | E2: 45955 | F2: 45959 | G2: 45964 | H2: =IF(G2="", "Not Delivered", "Delivered") -> Delivered | I2: No | J2: not cancelled | K2: 45989 | L2: 4 | M2: 4 | N2: 5 | O2: 2 | P2: {=_xlfn.IFS(O2<=6,"Detractors",AND(O2>=7,O2<=8),"Passives",AND(O2>8,O2<=10),"Promoters",O2="Not Available","NA")} -> Detractors
A3: L1001 | B3: Delhi MBC | C3: Warm | D3: 45941 | E3: 45944 | F3: 45949 | G3: 45956 | H3: =IF(G3="", "Not Delivered", "Delivered") -> Delivered | I3: No | J3: not cancelled | K3: 45983 | L3: 3 | M3: 5 | N3: 7 | O3: 8 | P3: {=_xlfn.IFS(O3<=6,"Detractors",AND(O3>=7,O3<=8),"Passives",AND(O3>8,O3<=10),"Promoters",O3="Not Available","NA")} -> Passives
A4: L1002 | B4: Mumbai MBC | C4: Cold | D4: 45931 | H4: =IF(G4="", "Not Delivered", "Delivered") -> Not Delivered | I4: Yes | J4: Other | L4: 0 | M4: 0 | N4: 0 | O4: Not Available | P4: {=_xlfn.IFS(O4<=6,"Detractors",AND(O4>=7,O4<=8),"Passives",AND(O4>8,O4<=10),"Promoters",O4="Not Available","NA")} -> NA
A5: L1003 | B5: Bangalore MBC | C5: Cold | D5: 45958 | H5: =IF(G5="", "Not Delivered", "Delivered") -> Not Delivered | I5: Yes | J5: Model Unavailable | L5: 0 | M5: 0 | N5: 0 | O5: Not Available | P5: {=_xlfn.IFS(O5<=6,"Detractors",AND(O5>=7,O5<=8),"Passives",AND(O5>8,O5<=10),"Promoters",O5="Not Available","NA")} -> NA
A6: L1004 | B6: Delhi MBC | C6: Warm | D6: 45944 | E6: 45948 | F6: 45951 | G6: 45954 | H6: =IF(G6="", "Not Delivered", "Delivered") -> Delivered | I6: No | J6: not cancelled | K6: 45973 | L6: 4 | M6: 3 | N6: 3 | O6: 8 | P6: {=_xlfn.IFS(O6<=6,"Detractors",AND(O6>=7,O6<=8),"Passives",AND(O6>8,O6<=10),"Promoters",O6="Not Available","NA")} -> Passives
A7: L1005 | B7: Delhi MBC | C7: Warm | D7: 45957 | E7: 45961 | F7: 45965 | G7: 45968 | H7: =IF(G7="", "Not Delivered", "Delivered") -> Delivered | I7: No | J7: not cancelled | K7: 45983 | L7: 4 | M7: 4 | N7: 3 | O7: 9 | P7: {=_xlfn.IFS(O7<=6,"Detractors",AND(O7>=7,O7<=8),"Passives",AND(O7>8,O7<=10),"Promoters",O7="Not Available","NA")} -> Promoters
A8: L1006 | B8: Mumbai MBC | C8: Hot | D8: 45946 | E8: 45950 | F8: 45951 | G8: 45958 | H8: =IF(G8="", "Not Delivered", "Delivered") -> Delivered | I8: No | J8: not cancelled | K8: 45983 | L8: 4 | M8: 1 | N8: 7 | O8: 10 | P8: {=_xlfn.IFS(O8<=6,"Detractors",AND(O8>=7,O8<=8),"Passives",AND(O8>8,O8<=10),"Promoters",O8="Not Available","NA")} -> Promoters
A9: L1007 | B9: Chennai MBC | C9: Warm | D9: 45934 | E9: 45935 | F9: 45938 | G9: 45945 | H9: =IF(G9="", "Not Delivered", "Delivered") -> Delivered | I9: Yes | J9: Changed Mind | L9: 1 | M9: 3 | N9: 7 | O9: Not Available | P9: {=_xlfn.IFS(O9<=6,"Detractors",AND(O9>=7,O9<=8),"Passives",AND(O9>8,O9<=10),"Promoters",O9="Not Available","NA")} -> NA
A10: L1008 | B10: Bangalore MBC | C10: Hot | D10: 45944 | E10: 45947 | F10: 45950 | G10: 45955 | H10: =IF(G10="", "Not Delivered", "Delivered") -> Delivered | I10: No | J10: not cancelled | K10: 45966 | L10: 3 | M10: 3 | N10: 5 | O10: 8 | P10: {=_xlfn.IFS(O10<=6,"Detractors",AND(O10>=7,O10<=8),"Passives",AND(O10>8,O10<=10),"Promoters",O10="Not Available","NA")} -> Passives
A11: L1009 | B11: Mumbai MBC | C11: Warm | D11: 45961 | E11: 45965 | F11: 45966 | G11: 45971 | H11: =IF(G11="", "Not Delivered", "Delivered") -> Delivered | I11: No | J11: not cancelled | K11: 45983 | L11: 4 | M11: 1 | N11: 5 | O11: 6 | P11: {=_xlfn.IFS(O11<=6,"Detractors",AND(O11>=7,O11<=8),"Passives",AND(O11>8,O11<=10),"Promoters",O11="Not Available","NA")} -> Detractors
A12: L1010 | B12: Bangalore MBC | C12: Cold | D12: 45942 | H12: =IF(G12="", "Not Delivered", "Delivered") -> Not Delivered | I12: Yes | J12: Other | L12: 0 | M12: 0 | N12: 0 | O12: Not Available | P12: {=_xlfn.IFS(O12<=6,"Detractors",AND(O12>=7,O12<=8),"Passives",AND(O12>8,O12<=10),"Promoters",O12="Not Available","NA")} -> NA
A13: L1011 | B13: Delhi MBC | C13: Warm | D13: 45951 | E13: 45954 | F13: 45958 | G13: 45960 | H13: =IF(G13="", "Not Delivered", "Delivered") -> Delivered | I13: No | J13: not cancelled | K13: 45971 | L13: 3 | M13: 4 | N13: 2 | O13: 0 | P13: {=_xlfn.IFS(O13<=6,"Detractors",AND(O13>=7,O13<=8),"Passives",AND(O13>8,O13<=10),"Promoters",O13="Not Available","NA")} -> Detractors
A14: L1012 | B14: Delhi MBC | C14: Warm | D14: 45959 | E14: 45962 | F14: 45967 | G14: 45974 | H14: =IF(G14="", "Not Delivered", "Delivered") -> Delivered | I14: No | J14: not cancelled | K14: 45991 | L14: 3 | M14: 5 | N14: 7 | O14: 10 | P14: {=_xlfn.IFS(O14<=6,"Detractors",AND(O14>=7,O14<=8),"Passives",AND(O14>8,O14<=10),"Promoters",O14="Not Available","NA")} -> Promoters
A15: L1013 | B15: Chennai MBC | C15: Warm | D15: 45957 | E15: 45960 | F15: 45963 | G15: 45969 | H15: =IF(G15="", "Not Delivered", "Delivered") -> Delivered | I15: No | J15: not cancelled | K15: 45998 | L15: 3 | M15: 3 | N15: 6 | O15: 2 | P15: {=_xlfn.IFS(O15<=6,"Detractors",AND(O15>=7,O15<=8),"Passives",AND(O15>8,O15<=10),"Promoters",O15="Not Available","NA")} -> Detractors
A16: L1014 | B16: Delhi MBC | C16: Hot | D16: 45945 | E16: 45947 | F16: 45948 | G16: 45951 | H16: =IF(G16="", "Not Delivered", "Delivered") -> Delivered | I16: Yes | J16: Changed Mind | L16: 2 | M16: 1 | N16: 3 | O16: Not Available | P16: {=_xlfn.IFS(O16<=6,"Detractors",AND(O16>=7,O16<=8),"Passives",AND(O16>8,O16<=10),"Promoters",O16="Not Available","NA")} -> NA
A17: L1015 | B17: Delhi MBC | C17: Warm | D17: 45953 | E17: 45957 | F17: 45962 | G17: 45967 | H17: =IF(G17="", "Not Delivered", "Delivered") -> Delivered | I17: No | J17: not cancelled | K17: 45984 | L17: 4 | M17: 5 | N17: 5 | O17: 8 | P17: {=_xlfn.IFS(O17<=6,"Detractors",AND(O17>=7,O17<=8),"Passives",AND(O17>8,O17<=10),"Promoters",O17="Not Available","NA")} -> Passives
A18: L1016 | B18: Mumbai MBC | C18: Hot | D18: 45935 | E18: 45936 | F18: 45940 | G18: 45946 | H18: =IF(G18="", "Not Delivered", "Delivered") -> Delivered | I18: No | J18: not cancelled | K18: 45956 | L18: 1 | M18: 4 | N18: 6 | O18: 2 | P18: {=_xlfn.IFS(O18<=6,"Detractors",AND(O18>=7,O18<=8),"Passives",AND(O18>8,O18<=10),"Promoters",O18="Not Available","NA")} -> Detractors
A19: L1017 | B19: Bangalore MBC | C19: Hot | D19: 45944 | E19: 45945 | F19: 45948 | G19: 45953 | H19: =IF(G19="", "Not Delivered", "Delivered") -> Delivered | I19: No | J19: not cancelled | K19: 45979 | L19: 1 | M19: 3 | N19: 5 | O19: 0 | P19: {=_xlfn.IFS(O19<=6,"Detractors",AND(O19>=7,O19<=8),"Passives",AND(O19>8,O19<=10),"Promoters",O19="Not Available","NA")} -> Detractors
A20: L1018 | B20: Bangalore MBC | C20: Warm | D20: 45936 | E20: 45937 | F20: 45942 | G20: 45947 | H20: =IF(G20="", "Not Delivered", "Delivered") -> Delivered | I20: No | J20: not cancelled | K20: 45972 | L20: 1 | M20: 5 | N20: 5 | O20: 5 | P20: {=_xlfn.IFS(O20<=6,"Detractors",AND(O20>=7,O20<=8),"Passives",AND(O20>8,O20<=10),"Promoters",O20="Not Available","NA")} -> Detractors
A21: L1019 | B21: Mumbai MBC | C21: Warm | D21: 45954 | E21: 45955 | F21: 45960 | G21: 45962 | H21: =IF(G21="", "Not Delivered", "Delivered") -> Delivered | I21: No | J21: not cancelled | K21: 45972 | L21: 1 | M21: 5 | N21: 2 | O21: 4 | P21: {=_xlfn.IFS(O21<=6,"Detractors",AND(O21>=7,O21<=8),"Passives",AND(O21>8,O21<=10),"Promoters",O21="Not Available","NA")} -> Detractors
A22: L1020 | B22: Chennai MBC | C22: Warm | D22: 45947 | E22: 45951 | F22: 45953 | G22: 45960 | H22: =IF(G22="", "Not Delivered", "Delivered") -> Delivered | I22: No | J22: not cancelled | K22: 45980 | L22: 4 | M22: 2 | N22: 7 | O22: 6 | P22: {=_xlfn.IFS(O22<=6,"Detractors",AND(O22>=7,O22<=8),"Passives",AND(O22>8,O22<=10),"Promoters",O22="Not Available","NA")} -> Detractors
A23: L1021 | B23: Bangalore MBC | C23: Hot | D23: 45961 | E23: 45962 | F23: 45963 | G23: 45966 | H23: =IF(G23="", "Not Delivered", "Delivered") -> Delivered | I23: No | J23: not cancelled | K23: 45995 | L23: 1 | M23: 1 | N23: 3 | O23: 3 | P23: {=_xlfn.IFS(O23<=6,"Detractors",AND(O23>=7,O23<=8),"Passives",AND(O23>8,O23<=10),"Promoters",O23="Not Available","NA")} -> Detractors
A24: L1022 | B24: Delhi MBC | C24: Warm | D24: 45951 | E24: 45954 | F24: 45959 | G24: 45962 | H24: =IF(G24="", "Not Delivered", "Delivered") -> Delivered | I24: No | J24: not cancelled | K24: 45978 | L24: 3 | M24: 5 | N24: 3 | O24: 8 | P24: {=_xlfn.IFS(O24<=6,"Detractors",AND(O24>=7,O24<=8),"Passives",AND(O24>8,O24<=10),"Promoters",O24="Not Available","NA")} -> Passives
A25: L1023 | B25: Bangalore MBC | C25: Warm | D25: 45939 | E25: 45941 | F25: 45945 | G25: 45949 | H25: =IF(G25="", "Not Delivered", "Delivered") -> Delivered | I25: No | J25: not cancelled | K25: 45963 | L25: 2 | M25: 4 | N25: 4 | O25: 3 | P25: {=_xlfn.IFS(O25<=6,"Detractors",AND(O25>=7,O25<=8),"Passives",AND(O25>8,O25<=10),"Promoters",O25="Not Available","NA")} -> Detractors
A26: L1024 | B26: Delhi MBC | C26: Warm | D26: 45950 | E26: 45955 | F26: 45957 | G26: 45964 | H26: =IF(G26="", "Not Delivered", "Delivered") -> Delivered | I26: No | J26: not cancelled | K26: 45984 | L26: 5 | M26: 2 | N26: 7 | O26: 1 | P26: {=_xlfn.IFS(O26<=6,"Detractors",AND(O26>=7,O26<=8),"Passives",AND(O26>8,O26<=10),"Promoters",O26="Not Available","NA")} -> Detractors
A27: L1025 | B27: Chennai MBC | C27: Warm | D27: 45956 | E27: 45957 | F27: 45962 | G27: 45964 | H27: =IF(G27="", "Not Delivered", "Delivered") -> Delivered | I27: No | J27: not cancelled | K27: 45979 | L27: 1 | M27: 5 | N27: 2 | O27: 4 | P27: {=_xlfn.IFS(O27<=6,"Detractors",AND(O27>=7,O27<=8),"Passives",AND(O27>8,O27<=10),"Promoters",O27="Not Available","NA")} -> Detractors
A28: L1026 | B28: Mumbai MBC | C28: Warm | D28: 45960 | E28: 45965 | F28: 45970 | G28: 45976 | H28: =IF(G28="", "Not Delivered", "Delivered") -> Delivered | I28: No | J28: not cancelled | K28: 45996 | L28: 5 | M28: 5 | N28: 6 | O28: 1 | P28: {=_xlfn.IFS(O28<=6,"Detractors",AND(O28>=7,O28<=8),"Passives",AND(O28>8,O28<=10),"Promoters",O28="Not Available","NA")} -> Detractors
... A30: L1028 | B30: Mumbai MBC | C30: Warm | D30: 45955 | E30: 45960 | F30: 45962 | G30: 45968 | H30: =IF(G30="", "Not Delivered", "Delivered") -> Delivered | I30: No | J30: not cancelled | K30: 45978 | L30: 5 | M30: 2 | N30: 6 | O30: 3 | P30: {=_xlfn.IFS(O30<=6,"Detractors",AND(O30>=7,O30<=8),"Passives",AND(O30>8,O30<=10),"Promoters",O30="Not Available","NA")} -> Detractors
A31: L1029 | B31: Bangalore MBC | C31: Cold | D31: 45946 | H31: =IF(G31="", "Not Delivered", "Delivered") -> Not Delivered | I31: Yes | J31: Changed Mind | L31: 0 | M31: 0 | N31: 0 | O31: Not Available | P31: {=_xlfn.IFS(O31<=6,"Detractors",AND(O31>=7,O31<=8),"Passives",AND(O31>8,O31<=10),"Promoters",O31="Not Available","NA")} -> NA
A32: L1030 | B32: Delhi MBC | C32: Warm | D32: 45945 | E32: 45948 | F32: 45950 | G32: 45953 | H32: =IF(G32="", "Not Delivered", "Delivered") -> Delivered | I32: No | J32: not cancelled | K32: 45967 | L32: 3 | M32: 2 | N32: 3 | O32: 3 | P32: {=_xlfn.IFS(O32<=6,"Detractors",AND(O32>=7,O32<=8),"Passives",AND(O32>8,O32<=10),"Promoters",O32="Not Available","NA")} -> Detractors
A33: L1031 | B33: Mumbai MBC | C33: Warm | D33: 45944 | E33: 45945 | F33: 45946 | G33: 45950 | H33: =IF(G33="", "Not Delivered", "Delivered") -> Delivered | I33: No | J33: not cancelled | K33: 45978 | L33: 1 | M33: 1 | N33: 4 | O33: 5 | P33: {=_xlfn.IFS(O33<=6,"Detractors",AND(O33>=7,O33<=8),"Passives",AND(O33>8,O33<=10),"Promoters",O33="Not Available","NA")} -> Detractors
A34: L1032 | B34: Bangalore MBC | C34: Warm | D34: 45957 | E34: 45961 | F34: 45966 | G34: 45970 | H34: =IF(G34="", "Not Delivered", "Delivered") -> Delivered | I34: No | J34: not cancelled | K34: 45984 | L34: 4 | M34: 5 | N34: 4 | O34: 3 | P34: {=_xlfn.IFS(O34<=6,"Detractors",AND(O34>=7,O34<=8),"Passives",AND(O34>8,O34<=10),"Promoters",O34="Not Available","NA")} -> Detractors
A35: L1033 | B35: Delhi MBC | C35: Warm | D35: 45954 | E35: 45957 | F35: 45958 | G35: 45961 | H35: =IF(G35="", "Not Delivered", "Delivered") -> Delivered | I35: No | J35: not cancelled | K35: 45974 | L35: 3 | M35: 1 | N35: 3 | O35: 3 | P35: {=_xlfn.IFS(O35<=6,"Detractors",AND(O35>=7,O35<=8),"Passives",AND(O35>8,O35<=10),"Promoters",O35="Not Available","NA")} -> Detractors
A36: L1034 | B36: Mumbai MBC | C36: Cold | D36: 45949 | H36: =IF(G36="", "Not Delivered", "Delivered") -> Not Delivered | I36: Yes | J36: Model Unavailable | L36: 0 | M36: 0 | N36: 0 | O36: Not Available | P36: {=_xlfn.IFS(O36<=6,"Detractors",AND(O36>=7,O36<=8),"Passives",AND(O36>8,O36<=10),"Promoters",O36="Not Available","NA")} -> NA
A37: L1035 | B37: Mumbai MBC | C37: Warm | D37: 45939 | E37: 45943 | F37: 45945 | G37: 45950 | H37: =IF(G37="", "Not Delivered", "Delivered") -> Delivered | I37: No | J37: not cancelled | K37: 45976 | L37: 4 | M37: 2 | N37: 5 | O37: 9 | P37: {=_xlfn.IFS(O37<=6,"Detractors",AND(O37>=7,O37<=8),"Passives",AND(O37>8,O37<=10),"Promoters",O37="Not Available","NA")} -> Promoters
A38: L1036 | B38: Bangalore MBC | C38: Warm | D38: 45941 | E38: 45942 | F38: 45943 | G38: 45945 | H38: =IF(G38="", "Not Delivered", "Delivered") -> Delivered | I38: Yes | J38: Financing Issue | L38: 1 | M38: 1 | N38: 2 | O38: Not Available | P38: {=_xlfn.IFS(O38<=6,"Detractors",AND(O38>=7,O38<=8),"Passives",AND(O38>8,O38<=10),"Promoters",O38="Not Available","NA")} -> NA
A39: L1037 | B39: Bangalore MBC | C39: Warm | D39: 45958 | E39: 45961 | F39: 45965 | G39: 45969 | H39: =IF(G39="", "Not Delivered", "Delivered") -> Delivered | I39: No | J39: not cancelled | K39: 45990 | L39: 3 | M39: 4 | N39: 4 | O39: 2 | P39: {=_xlfn.IFS(O39<=6,"Detractors",AND(O39>=7,O39<=8),"Passives",AND(O39>8,O39<=10),"Promoters",O39="Not Available","NA")} -> Detractors
A40: L1038 | B40: Bangalore MBC | C40: Warm | D40: 45938 | E40: 45943 | F40: 45946 | G40: 45953 | H40: =IF(G40="", "Not Delivered", "Delivered") -> Delivered | I40: No | J40: not cancelled | K40: 45965 | L40: 5 | M40: 3 | N40: 7 | O40: 9 | P40: {=_xlfn.IFS(O40<=6,"Detractors",AND(O40>=7,O40<=8),"Passives",AND(O40>8,O40<=10),"Promoters",O40="Not Available","NA")} -> Promoters
A41: L1039 | B41: Delhi MBC | C41: Warm | D41: 45957 | E41: 45960 | F41: 45964 | G41: 45969 | H41: =IF(G41="", "Not Delivered", "Delivered") -> Delivered | I41: Yes | J41: Other | L41: 3 | M41: 4 | N41: 5 | O41: Not Available | P41: {=_xlfn.IFS(O41<=6,"Detractors",AND(O41>=7,O41<=8),"Passives",AND(O41>8,O41<=10),"Promoters",O41="Not Available","NA")} -> NA
...

Sheet Solutions
A1: Question 1.1: Conversion rates
A2: The analysis for this question is done by using Pivot Table.
D5: Store Name | E5: Count of Lead Date | F5: Count of Pre-Booking Date | G5: Count of Booking Date | H5: Count of Delivery Date
D6: Bangalore MBC | E6: 263 | F6: 212 | G6: 212 | H6: 212
D7: Chennai MBC | E7: 212 | F7: 173 | G7: 173 | H7: 173
D8: Delhi MBC | E8: 263 | F8: 212 | G8: 212 | H8: 212
D9: Mumbai MBC | E9: 262 | F9: 215 | G9: 215 | H9: 215
D10: Grand Total | E10: 1000 | F10: 812 | G10: 812 | H10: 812
A12: Conversion at each stage | D12: Store Room | E12: Count of Lead Date | F12: Count of Pre-Booking Date | G12: Count of Booking Date | H12: Count of Delhivery Date | I12: Conversion from Lead to Pre-Booking | J12: Conversion from Pre-Booking to Booking | K12: Conversion from Booking to Delivery
D13: Bangalore MBC | E13: =COUNTIFS(Sheet1!$B:$B,Solutions!D13) -> 263 | F13: 212 | G13: 212 | H13: 212 | I13: =F13/E13 -> 0.80608365 | J13: =G13/F13 -> 1 | K13: =H13/G13 -> 1
D14: Chennai MBC | E14: =COUNTIFS(Sheet1!$B:$B,Solutions!D14) -> 212 | F14: 173 | G14: 173 | H14: 173 | I14: =F14/E14 -> 0.81603774 | J14: =G14/F14 -> 1 | K14: =H14/G14 -> 1
D15: Delhi MBC | E15: =COUNTIFS(Sheet1!$B:$B,Solutions!D15) -> 263 | F15: 212 | G15: 212 | H15: 212 | I15: =F15/E15 -> 0.80608365 | J15: =G15/F15 -> 1 | K15: =H15/G15 -> 1
D16: Mumbai MBC | E16: =COUNTIFS(Sheet1!$B:$B,Solutions!D16) -> 262 | F16: 215 | G16: 215 | H16: 215 | I16: =F16/E16 -> 0.82061069 | J16: =G16/F16 -> 1 | K16: =H16/G16 -> 1
A18: Final Conversion | D18: Store Room | E18: Conversion from Lead Date to Delivery
D19: Bangalore MBC | E19: =H13/E13 -> 0.80608365
D20: Chennai MBC | E20: =H14/E14 -> 0.81603774
D21: Delhi MBC | E21: =H15/E15 -> 0.80608365
D22: Mumbai MBC | E22: =H16/E16 -> 0.82061069
A30: Question 1.2: Average TAT for each stage per store
A31: The analysis for this question is done by using Pivot Table.
D34: Store Name | E34: Average of TAT Pre-Booking (Days) | F34: Average of TAT Booking (Days) | G34: Average of TAT Delivery (Days)
D35: Bangalore MBC | E35: 3.1179245 | F35: 3.0330189 | G35: 4.5141509
D36: Chennai MBC | E36: 3.1213873 | F36: 3.2023121 | G36: 4.3872832
D37: Delhi MBC | E37: 3.0283019 | F37: 3.0188679 | G37: 4.2830189
D38: Mumbai MBC | E38: 2.9767442 | F38: 3.0465116 | G38: 4.627907
D39: Grand Total | E39: 3.0578818 | F39: 3.0689655 | G39: 4.4568966
D42: Store Name | E42: Avg. TAT for Lead to Pre-Booking stage | F42: Avg. TAT for Pre-Booking to Booking stage | G42: Avg. TAT for Booking to Delivery stage
D43: Bangalore MBC | E43: 3.1179245 | F43: 3.0330189 | G43: 4.5141509
D44: Chennai MBC | E44: 3.1213873 | F44: 3.2023121 | G44: 4.3872832
D45: Delhi MBC | E45: 3.0283019 | F45: 3.0188679 | G45: 4.2830189
D46: Mumbai MBC | E46: 2.9767442 | F46: 3.0465116 | G46: 4.627907
A53: Question 1.3: Cancellation patterns by store and reason
A54: The analysis for this question is done by using Excel Formulas.
D57: Count of Lead ID | E57: Cancellation Status
D58: Store Name | E58: Changed Mind | F58: Financing Issue | G58: Model Unavailable | H58: Other | I58: Price | J58: Grand Total
D59: Bangalore MBC | E59: 13 | F59: 14 | G59: 13 | H59: 22 | I59: 10 | J59: 72
D60: Chennai MBC | E60: 15 | F60: 10 | G60: 8 | H60: 8 | I60: 18 | J60: 59
D61: Delhi MBC | E61: 14 | F61: 21 | G61: 13 | H61: 13 | I61: 16 | J61: 77
D62: Mumbai MBC | E62: 9 | F62: 14 | G62: 9 | H62: 14 | I62: 17 | J62: 63
D63: Grand Total | E63: 51 | F63: 59 | G63: 43 | H63: 57 | I63: 61 | J63: 271
...

Sheet Dashboard_
V16: Select Store Name | W16: Cancellation Reason | X16: Total Number
V17: Chennai MBC | W17: Changed Mind | X17: =COUNTIFS(Sheet1!$B:$B,$V$17,Sheet1!$J:$J,W17) -> 15
W18: Financing issue | X18: =COUNTIFS(Sheet1!$B:$B,$V$17,Sheet1!$J:$J,W18) -> 10
W19: Model Unavailable | X19: =COUNTIFS(Sheet1!$B:$B,$V$17,Sheet1!$J:$J,W19) -> 8
W20: Other | X20: =COUNTIFS(Sheet1!$B:$B,$V$17,Sheet1!$J:$J,W20) -> 8
W21: Price | X21: =COUNTIFS(Sheet1!$B:$B,$V$17,Sheet1!$J:$J,W21) -> 18
W22: Total | X22: =SUM(X17:X21) -> 59
Q34: Select Store Name | R34: Reviewers | S34: Number of Customers
G35: Select Store Name | H35: Lead Type | I35: Number of Leads | Q35: Mumbai MBC | R35: Promoters | S35: =COUNTIFS(Sheet1!$B:$B,$Q$35,Sheet1!$P:$P,R35) -> 23
G36: Bangalore MBC | H36: Hot | I36: =COUNTIFS(Sheet1!$C:$C, H36,Sheet1!$B:$B,$G$36) -> 80 | R36: Passives | S36: =COUNTIFS(Sheet1!$B:$B,$Q$35,Sheet1!$P:$P,R36) -> 38
H37: Cold | I37: =COUNTIFS(Sheet1!$C:$C, H37,Sheet1!$B:$B,$G$36) -> 51 | R37: Detractors | S37: =COUNTIFS(Sheet1!$B:$B,$Q$35,Sheet1!$P:$P,R37) -> 138
H38: Warm | I38: =COUNTIFS(Sheet1!$C:$C, H38,Sheet1!$B:$B,$G$36) -> 132 | R38: Total | S38: =SUM(S35:S37) -> 199
H39: Total | I39: =SUM(I36:I38) -> 263
I47: Select Store Name | J47: Select Lead Type | K47: Customer Rating | L47: Total count of Customers | S47: All the Analysis and Dashboarding is done in MS Excel 2021.
I48: Delhi MBC | J48: Hot | K48: 0 | L48: =COUNTIFS(Sheet1!$B:$B,$I$48,Sheet1!$C:$C,$J$48,Sheet1!$O:$O,K48) -> 1
K49: 1 | L49: =COUNTIFS(Sheet1!$B:$B,$I$48,Sheet1!$C:$C,$J$48,Sheet1!$O:$O,K49) -> 5
K50: 2 | L50: =COUNTIFS(Sheet1!$B:$B,$I$48,Sheet1!$C:$C,$J$48,Sheet1!$O:$O,K50) -> 8
K51: 3 | L51: =COUNTIFS(Sheet1!$B:$B,$I$48,Sheet1!$C:$C,$J$48,Sheet1!$O:$O,K51) -> 8
K52: 4 | L52: =COUNTIFS(Sheet1!$B:$B,$I$48,Sheet1!$C:$C,$J$48,Sheet1!$O:$O,K52) -> 7
K53: 5 | L53: =COUNTIFS(Sheet1!$B:$B,$I$48,Sheet1!$C:$C,$J$48,Sheet1!$O:$O,K53) -> 4
K54: 6 | L54: =COUNTIFS(Sheet1!$B:$B,$I$48,Sheet1!$C:$C,$J$48,Sheet1!$O:$O,K54) -> 7
K55: 7 | L55: =COUNTIFS(Sheet1!$B:$B,$I$48,Sheet1!$C:$C,$J$48,Sheet1!$O:$O,K55) -> 9
K56: 8 | L56: =COUNTIFS(Sheet1!$B:$B,$I$48,Sheet1!$C:$C,$J$48,Sheet1!$O:$O,K56) -> 2
K57: 9 | L57: =COUNTIFS(Sheet1!$B:$B,$I$48,Sheet1!$C:$C,$J$48,Sheet1!$O:$O,K57) -> 4
K58: 10 | L58: =COUNTIFS(Sheet1!$B:$B,$I$48,Sheet1!$C:$C,$J$48,Sheet1!$O:$O,K58) -> 4

Sheet Dashboard
N26: ="Total Cancellation from store:" &M29 -> Total Cancellation from store:Bangalore MBC
M28: Select Store Name | N28: Cancellation Reason | O28: Total Number
M29: Bangalore MBC | N29: Changed Mind | O29: =COUNTIFS(Sheet1!$B:$B,Dashboard!$M$29,Sheet1!$J:$J,Dashboard!N29) -> 13
N30: Financing issue | O30: =COUNTIFS(Sheet1!$B:$B,Dashboard!$M$29,Sheet1!$J:$J,Dashboard!N30) -> 14
N31: Model Unavailable | O31: =COUNTIFS(Sheet1!$B:$B,Dashboard!$M$29,Sheet1!$J:$J,Dashboard!N31) -> 13
N32: Other | O32: =COUNTIFS(Sheet1!$B:$B,Dashboard!$M$29,Sheet1!$J:$J,Dashboard!N32) -> 22
N33: Price | O33: =COUNTIFS(Sheet1!$B:$B,Dashboard!$M$29,Sheet1!$J:$J,Dashboard!N33) -> 10
N34: Total | O34: =SUM(O29:O33) -> 72
N48: ="Total No. of Lead Type from store:" &M51 -> Total No. of Lead Type from store:Mumbai MBC
M50: Select Store Name | N50: Lead Type | O50: Number of Leads
M51: Mumbai MBC | N51: Hot | O51: =COUNTIFS(Sheet1!$C:$C, Dashboard!N51,Sheet1!$B:$B,Dashboard!$M$51) -> 83
N52: Cold | O52: =COUNTIFS(Sheet1!$C:$C, Dashboard!N52,Sheet1!$B:$B,Dashboard!$M$51) -> 47
N53: Warm | O53: =COUNTIFS(Sheet1!$C:$C, Dashboard!N53,Sheet1!$B:$B,Dashboard!$M$51) -> 132
N54: Total | O54: =SUM(O51:O53) -> 262
M68: Select Store Name | N68: Select Lead Type | O68: Customer Rating | P68: Total count of Customers
M69: Delhi MBC | N69: Warm | O69: 0 | P69: =COUNTIFS(Sheet1!$B:$B,Dashboard!$M$69,Sheet1!$C:$C,Dashboard!$N$69,Sheet1!$O:$O,Dashboard!O69) -> 9
O70: 1 | P70: =COUNTIFS(Sheet1!$B:$B,Dashboard!$M$69,Sheet1!$C:$C,Dashboard!$N$69,Sheet1!$O:$O,Dashboard!O70) -> 16
O71: 2 | P71: =COUNTIFS(Sheet1!$B:$B,Dashboard!$M$69,Sheet1!$C:$C,Dashboard!$N$69,Sheet1!$O:$O,Dashboard!O71) -> 13
O72: 3 | P72: =COUNTIFS(Sheet1!$B:$B,Dashboard!$M$69,Sheet1!$C:$C,Dashboard!$N$69,Sheet1!$O:$O,Dashboard!O72) -> 8
O73: 4 | P73: =COUNTIFS(Sheet1!$B:$B,Dashboard!$M$69,Sheet1!$C:$C,Dashboard!$N$69,Sheet1!$O:$O,Dashboard!O73) -> 16
O74: 5 | P74: =COUNTIFS(Sheet1!$B:$B,Dashboard!$M$69,Sheet1!$C:$C,Dashboard!$N$69,Sheet1!$O:$O,Dashboard!O74) -> 6
O75: 6 | P75: =COUNTIFS(Sheet1!$B:$B,Dashboard!$M$69,Sheet1!$C:$C,Dashboard!$N$69,Sheet1!$O:$O,Dashboard!O75) -> 15
O76: 7 | P76: =COUNTIFS(Sheet1!$B:$B,Dashboard!$M$69,Sheet1!$C:$C,Dashboard!$N$69,Sheet1!$O:$O,Dashboard!O76) -> 10
O77: 8 | P77: =COUNTIFS(Sheet1!$B:$B,Dashboard!$M$69,Sheet1!$C:$C,Dashboard!$N$69,Sheet1!$O:$O,Dashboard!O77) -> 12
O78: 9 | P78: =COUNTIFS(Sheet1!$B:$B,Dashboard!$M$69,Sheet1!$C:$C,Dashboard!$N$69,Sheet1!$O:$O,Dashboard!O78) -> 15
O79: 10 | P79: =COUNTIFS(Sheet1!$B:$B,Dashboard!$M$69,Sheet1!$C:$C,Dashboard!$N$69,Sheet1!$O:$O,Dashboard!O79) -> 7
M88: Select Store Name | N88: Reviewers | O88: Number of Customers
M89: Delhi MBC | N89: Promoters | O89: =COUNTIFS(Sheet1!$B:$B,Dashboard!$M$89,Sheet1!$P:$P,Dashboard!N89) -> 30
N90: Passives | O90: =COUNTIFS(Sheet1!$B:$B,Dashboard!$M$89,Sheet1!$P:$P,Dashboard!N90) -> 33
N91: Detractors | O91: =COUNTIFS(Sheet1!$B:$B,Dashboard!$M$89,Sheet1!$P:$P,Dashboard!N91) -> 123
N92: Total | O92: =SUM(O89:O91) -> 186
